Workbook

Sheet Legend and Setup
A1: KenAddme IT Links - Project Build Status Tracker
A2: Two aligned governance tracks: Project Management (Gates 1-7) and Software Development & Engineering (G0-G6)
A4: How to use this workbook
A5: - Fill in only the shaded cells. Every unshaded cell is either a heading, a framework requirement or a formula.
A6: - Project details below feed nothing automatically - they are the controlled header for the whole tracker. Complete them first.
A7: - 'PM Track' and 'SDLC Track' hold one row per mandatory evidence item. Set the Status column from the drop-down list, name an owner, and record where the evidence actually lives.
A8: - 'Dashboard' calculates gate completion from those two sheets. Do not type over its formulas.
A9: - Set a row to 'Not applicable' only where tailoring permits it. Tailoring must not fall below the Appendix A artefact floor without an approved exception - log that exception on the 'Exceptions' sheet.
A10: - A gate is not passed because the work is finished. It is passed when the evidence exists, the named authority decides, and the decision is recorded.
A12: Example of a completed tracker row
A13: Column | B13: Example entry | C13: Note
A14: Gate | B14: G2 | C14: Pre-filled - do not edit
A15: Required evidence | B15: Threat model and privacy assessment | C15: Pre-filled - do not edit
A16: Status | B16: Complete | C16: Choose from the drop-down list
A17: Owner | B17: A. Mensah, Security and Privacy Reviewer | C17: One named person, not a team
A18: Due date | B18: 2026-10-24 | C18: Use YYYY-MM-DD
A19: Date completed | B19: 2026-10-21 | C19: Blank until the evidence is accepted
A20: Evidence reference | B20: REPO/docs/security/threat-model-v2.md (rev 2026-10-21) | C20: Where the record actually lives
A21: Notes | B21: Two residual risks accepted by the Sponsor at G2 | C21: Conditions, deviations, links
A23: Project details
A24: Field | B24: Value | C24: Guidance
A25: Project / product name | C25: Name as it appears in the project register
A26: Project register ID | C26: Unique reference
A27: Project class (PM) | C27: Class A - Strategic/High Risk | Class B - Standard/Medium Risk | Class C - Small/Low Risk
A28: Software class (SDLC) | C28: Class 1 Experimental | Class 2 Standard | Class 3 High | Class 4 Critical
A29: Classification rationale | C29: Highest applicable condition controls the class
A30: Executive / Project Authority | C30: Chair or recorded delegate
A31: Project Sponsor | C31: Accountable business owner
A32: Project Manager / Delivery Lead | C32: Cannot approve own charter, baseline, change, release, acceptance or closure
A33: Product / Business Owner
A34: Technical Lead / Solution Architect
A35: Quality / Assurance Reviewer | C35: Independence depth follows the higher class
A36: Security / Privacy Reviewer | C36: Distinct control role for higher-risk work
A37: Service / Operations Owner | C37: Owns operational acceptance and benefits evidence
A38: Release Authority | C38: Executive Sponsor or delegate for Class 3-4; Technical Lead for Class 1-2
A39: Data Owner
A40: Cost baseline (GHS) | C40: Approved baseline excluding contingency
A41: Cost tolerance | C41: Class A +/-5%, Class B +/-10%, Class C +/-15%
A42: Schedule tolerance | C42: Class A +/-5%, Class B +/-10%, Class C +/-15%
A43: Baseline start date
...

Sheet Dashboard
A1: Build status dashboard
A2: Counts are calculated from the two track sheets. Record the gate decision and date here once the named authority has decided.
A4: Track | B4: Gate | C4: Decision point | D4: Items | E4: Complete | F4: In progress | G4: Not applicable | H4: Outstanding | I4: % complete | J4: Evidence position | K4: Gate decision | L4: Decision date
A5: PM | B5: Gate 1 | C5: Intake decision | D5: =COUNTIF('PM Gates 1-7'!$A$5:$A$101,B5) -> 11 | E5: =COUNTIFS('PM Gates 1-7'!$A$5:$A$101,B5,'PM Gates 1-7'!$G$5:$G$101,"Complete") -> 0 | F5: =COUNTIFS('PM Gates 1-7'!$A$5:$A$101,B5,'PM Gates 1-7'!$G$5:$G$101,"In progress")+COUNTIFS('PM Gates 1-7'!$A$5:$A$101,B5,'PM Gates 1-7'!$G$5:$G$101,"Submitted for review") -> 0 | G5: =COUNTIFS('PM Gates 1-7'!$A$5:$A$101,B5,'PM Gates 1-7'!$G$5:$G$101,"Not applicable")+COUNTIFS('PM Gates 1-7'!$A$5:$A$101,B5,'PM Gates 1-7'!$G$5:$G$101,"Exception approved") -> 0 | H5: =D5-E5-G5 -> 11 | I5: =IFERROR(E5/(D5-G5),0) -> 0 | J5: =IF(D5-G5=0,"All items tailored out",IF(H5=0,"Evidence complete",H5&" item(s) outstanding")) -> 11 item(s) outstanding | K5: Not yet held
A6: PM | B6: Gate 2 | C6: Project authorisation | D6: =COUNTIF('PM Gates 1-7'!$A$5:$A$101,B6) -> 12 | E6: =COUNTIFS('PM Gates 1-7'!$A$5:$A$101,B6,'PM Gates 1-7'!$G$5:$G$101,"Complete") -> 0 | F6: =COUNTIFS('PM Gates 1-7'!$A$5:$A$101,B6,'PM Gates 1-7'!$G$5:$G$101,"In progress")+COUNTIFS('PM Gates 1-7'!$A$5:$A$101,B6,'PM Gates 1-7'!$G$5:$G$101,"Submitted for review") -> 0 | G6: =COUNTIFS('PM Gates 1-7'!$A$5:$A$101,B6,'PM Gates 1-7'!$G$5:$G$101,"Not applicable")+COUNTIFS('PM Gates 1-7'!$A$5:$A$101,B6,'PM Gates 1-7'!$G$5:$G$101,"Exception approved") -> 0 | H6: =D6-E6-G6 -> 12 | I6: =IFERROR(E6/(D6-G6),0) -> 0 | J6: =IF(D6-G6=0,"All items tailored out",IF(H6=0,"Evidence complete",H6&" item(s) outstanding")) -> 12 item(s) outstanding | K6: Not yet held
A7: PM | B7: Gate 3 | C7: Delivery readiness | D7: =COUNTIF('PM Gates 1-7'!$A$5:$A$101,B7) -> 16 | E7: =COUNTIFS('PM Gates 1-7'!$A$5:$A$101,B7,'PM Gates 1-7'!$G$5:$G$101,"Complete") -> 0 | F7: =COUNTIFS('PM Gates 1-7'!$A$5:$A$101,B7,'PM Gates 1-7'!$G$5:$G$101,"In progress")+COUNTIFS('PM Gates 1-7'!$A$5:$A$101,B7,'PM Gates 1-7'!$G$5:$G$101,"Submitted for review") -> 0 | G7: =COUNTIFS('PM Gates 1-7'!$A$5:$A$101,B7,'PM Gates 1-7'!$G$5:$G$101,"Not applicable")+COUNTIFS('PM Gates 1-7'!$A$5:$A$101,B7,'PM Gates 1-7'!$G$5:$G$101,"Exception approved") -> 0 | H7: =D7-E7-G7 -> 16 | I7: =IFERROR(E7/(D7-G7),0) -> 0 | J7: =IF(D7-G7=0,"All items tailored out",IF(H7=0,"Evidence complete",H7&" item(s) outstanding")) -> 16 item(s) outstanding | K7: Not yet held
A8: PM | B8: Gate 4 | C8: Major deliverable or release readiness | D8: =COUNTIF('PM Gates 1-7'!$A$5:$A$101,B8) -> 12 | E8: =COUNTIFS('PM Gates 1-7'!$A$5:$A$101,B8,'PM Gates 1-7'!$G$5:$G$101,"Complete") -> 0 | F8: =COUNTIFS('PM Gates 1-7'!$A$5:$A$101,B8,'PM Gates 1-7'!$G$5:$G$101,"In progress")+COUNTIFS('PM Gates 1-7'!$A$5:$A$101,B8,'PM Gates 1-7'!$G$5:$G$101,"Submitted for review") -> 0 | G8: =COUNTIFS('PM Gates 1-7'!$A$5:$A$101,B8,'PM Gates 1-7'!$G$5:$G$101,"Not applicable")+COUNTIFS('PM Gates 1-7'!$A$5:$A$101,B8,'PM Gates 1-7'!$G$5:$G$101,"Exception approved") -> 0 | H8: =D8-E8-G8 -> 12 | I8: =IFERROR(E8/(D8-G8),0) -> 0 | J8: =IF(D8-G8=0,"All items tailored out",IF(H8=0,"Evidence complete",H8&" item(s) outstanding")) -> 12 item(s) outstanding | K8: Not yet held
A9: PM | B9: Gate 5 | C9: Continuation or exception decision | D9: =COUNTIF('PM Gates 1-7'!$A$5:$A$101,B9) -> 10 | E9: =COUNTIFS('PM Gates 1-7'!$A$5:$A$101,B9,'PM Gates 1-7'!$G$5:$G$101,"Complete") -> 0 | F9: =COUNTIFS('PM Gates 1-7'!$A$5:$A$101,B9,'PM Gates 1-7'!$G$5:$G$101,"In progress")+COUNTIFS('PM Gates 1-7'!$A$5:$A$101,B9,'PM Gates 1-7'!$G$5:$G$101,"Submitted for review") -> 0 | G9: =COUNTIFS('PM Gates 1-7'!$A$5:$A$101,B9,'PM Gates 1-7'!$G$5:$G$101,"Not applicable")+COUNTIFS('PM Gates 1-7'!$A$5:$A$101,B9,'PM Gates 1-7'!$G$5:$G$101,"Exception approved") -> 0 | H9: =D9-E9-G9 -> 10 | I9: =IFERROR(E9/(D9-G9),0) -> 0 | J9: =IF(D9-G9=0,"All items tailored out",IF(H9=0,"Evidence complete",H9&" item(s) outstanding")) -> 10 item(s) outstanding | K9: Not yet held
A10: PM | B10: Gate 6 | C10: Closure approval | D10: =COUNTIF('PM Gates 1-7'!$A$5:$A$101,B10) -> 12 | E10: =COUNTIFS('PM Gates 1-7'!$A$5:$A$101,B10,'PM Gates 1-7'!$G$5:$G$101,"Complete") -> 0 | F10: =COUNTIFS('PM Gates 1-7'!$A$5:$A$101,B10,'PM Gates 1-7'!$G$5:$G$101,"In progress")+COUNTIFS('PM Gates 1-7'!$A$5:$A$101,B10,'PM Gates 1-7'!$G$5:$G$101,"Submitted for review") -> 0 | G10: =COUNTIFS('PM Gates 1-7'!$A$5:$A$101,B10,'PM Gates 1-7'!$G$5:$G$101,"Not applicable")+COUNTIFS('PM Gates 1-7'!$A$5:$A$101,B10,'PM Gates 1-7'!$G$5:$G$101,"Exception approved") -> 0 | H10: =D10-E10-G10 -> 12 | I10: =IFERROR(E10/(D10-G10),0) -> 0 | J10: =IF(D10-G10=0,"All items tailored out",IF(H10=0,"Evidence complete",H10&" item(s) outstanding")) -> 12 item(s) outstanding | K10: Not yet held
A11: PM | B11: Gate 7 | C11: Benefits confirmation | D11: =COUNTIF('PM Gates 1-7'!$A$5:$A$101,B11) -> 10 | E11: =COUNTIFS('PM Gates 1-7'!$A$5:$A$101,B11,'PM Gates 1-7'!$G$5:$G$101,"Complete") -> 0 | F11: =COUNTIFS('PM Gates 1-7'!$A$5:$A$101,B11,'PM Gates 1-7'!$G$5:$G$101,"In progress")+COUNTIFS('PM Gates 1-7'!$A$5:$A$101,B11,'PM Gates 1-7'!$G$5:$G$101,"Submitted for review") -> 0 | G11: =COUNTIFS('PM Gates 1-7'!$A$5:$A$101,B11,'PM Gates 1-7'!$G$5:$G$101,"Not applicable")+COUNTIFS('PM Gates 1-7'!$A$5:$A$101,B11,'PM Gates 1-7'!$G$5:$G$101,"Exception approved") -> 0 | H11: =D11-E11-G11 -> 10 | I11: =IFERROR(E11/(D11-G11),0) -> 0 | J11: =IF(D11-G11=0,"All items tailored out",IF(H11=0,"Evidence complete",H11&" item(s) outstanding")) -> 10 item(s) outstanding | K11: Not yet held
A12: PM | B12: All | C12: Track total | D12: =SUM(D5:D11) -> 83 | E12: =SUM(E5:E11) -> 0 | F12: =SUM(F5:F11) -> 0 | G12: =SUM(G5:G11) -> 0 | H12: =SUM(H5:H11) -> 83 | I12: =IFERROR(E12/(D12-G12),0) -> 0 | J12: =IF(H12=0,"All required evidence recorded",H12&" item(s) outstanding across the track") -> 83 item(s) outstanding across the track
A14: SDLC | B14: G0 | C14: Intake | D14: =COUNTIF('SDLC G0-G6'!$A$5:$A$109,B14) -> 8 | E14: =COUNTIFS('SDLC G0-G6'!$A$5:$A$109,B14,'SDLC G0-G6'!$G$5:$G$109,"Complete") -> 0 | F14: =COUNTIFS('SDLC G0-G6'!$A$5:$A$109,B14,'SDLC G0-G6'!$G$5:$G$109,"In progress")+COUNTIFS('SDLC G0-G6'!$A$5:$A$109,B14,'SDLC G0-G6'!$G$5:$G$109,"Submitted for review") -> 0 | G14: =COUNTIFS('SDLC G0-G6'!$A$5:$A$109,B14,'SDLC G0-G6'!$G$5:$G$109,"Not applicable")+COUNTIFS('SDLC G0-G6'!$A$5:$A$109,B14,'SDLC G0-G6'!$G$5:$G$109,"Exception approved") -> 0 | H14: =D14-E14-G14 -> 8 | I14: =IFERROR(E14/(D14-G14),0) -> 0 | J14: =IF(D14-G14=0,"All items tailored out",IF(H14=0,"Evidence complete",H14&" item(s) outstanding")) -> 8 item(s) outstanding | K14: Not yet held
A15: SDLC | B15: G1 | C15: Requirements baseline | D15: =COUNTIF('SDLC G0-G6'!$A$5:$A$109,B15) -> 12 | E15: =COUNTIFS('SDLC G0-G6'!$A$5:$A$109,B15,'SDLC G0-G6'!$G$5:$G$109,"Complete") -> 0 | F15: =COUNTIFS('SDLC G0-G6'!$A$5:$A$109,B15,'SDLC G0-G6'!$G$5:$G$109,"In progress")+COUNTIFS('SDLC G0-G6'!$A$5:$A$109,B15,'SDLC G0-G6'!$G$5:$G$109,"Submitted for review") -> 0 | G15: =COUNTIFS('SDLC G0-G6'!$A$5:$A$109,B15,'SDLC G0-G6'!$G$5:$G$109,"Not applicable")+COUNTIFS('SDLC G0-G6'!$A$5:$A$109,B15,'SDLC G0-G6'!$G$5:$G$109,"Exception approved") -> 0 | H15: =D15-E15-G15 -> 12 | I15: =IFERROR(E15/(D15-G15),0) -> 0 | J15: =IF(D15-G15=0,"All items tailored out",IF(H15=0,"Evidence complete",H15&" item(s) outstanding")) -> 12 item(s) outstanding | K15: Not yet held
A16: SDLC | B16: G2 | C16: Design readiness | D16: =COUNTIF('SDLC G0-G6'!$A$5:$A$109,B16) -> 11 | E16: =COUNTIFS('SDLC G0-G6'!$A$5:$A$109,B16,'SDLC G0-G6'!$G$5:$G$109,"Complete") -> 0 | F16: =COUNTIFS('SDLC G0-G6'!$A$5:$A$109,B16,'SDLC G0-G6'!$G$5:$G$109,"In progress")+COUNTIFS('SDLC G0-G6'!$A$5:$A$109,B16,'SDLC G0-G6'!$G$5:$G$109,"Submitted for review") -> 0 | G16: =COUNTIFS('SDLC G0-G6'!$A$5:$A$109,B16,'SDLC G0-G6'!$G$5:$G$109,"Not applicable")+COUNTIFS('SDLC G0-G6'!$A$5:$A$109,B16,'SDLC G0-G6'!$G$5:$G$109,"Exception approved") -> 0 | H16: =D16-E16-G16 -> 11 | I16: =IFERROR(E16/(D16-G16),0) -> 0 | J16: =IF(D16-G16=0,"All items tailored out",IF(H16=0,"Evidence complete",H16&" item(s) outstanding")) -> 11 item(s) outstanding | K16: Not yet held
A17: SDLC | B17: G3 | C17: Code complete | D17: =COUNTIF('SDLC G0-G6'!$A$5:$A$109,B17) -> 13 | E17: =COUNTIFS('SDLC G0-G6'!$A$5:$A$109,B17,'SDLC G0-G6'!$G$5:$G$109,"Complete") -> 0 | F17: =COUNTIFS('SDLC G0-G6'!$A$5:$A$109,B17,'SDLC G0-G6'!$G$5:$G$109,"In progress")+COUNTIFS('SDLC G0-G6'!$A$5:$A$109,B17,'SDLC G0-G6'!$G$5:$G$109,"Submitted for review") -> 0 | G17: =COUNTIFS('SDLC G0-G6'!$A$5:$A$109,B17,'SDLC G0-G6'!$G$5:$G$109,"Not applicable")+COUNTIFS('SDLC G0-G6'!$A$5:$A$109,B17,'SDLC G0-G6'!$G$5:$G$109,"Exception approved") -> 0 | H17: =D17-E17-G17 -> 13 | I17: =IFERROR(E17/(D17-G17),0) -> 0 | J17: =IF(D17-G17=0,"All items tailored out",IF(H17=0,"Evidence complete",H17&" item(s) outstanding")) -> 13 item(s) outstanding | K17: Not yet held
A18: SDLC | B18: G4-R | C18: Release recommendation (verification and acceptance) | D18: =COUNTIF('SDLC G0-G6'!$A$5:$A$109,B18) -> 11 | E18: =COUNTIFS('SDLC G0-G6'!$A$5:$A$109,B18,'SDLC G0-G6'!$G$5:$G$109,"Complete") -> 0 | F18: =COUNTIFS('SDLC G0-G6'!$A$5:$A$109,B18,'SDLC G0-G6'!$G$5:$G$109,"In progress")+COUNTIFS('SDLC G0-G6'!$A$5:$A$109,B18,'SDLC G0-G6'!$G$5:$G$109,"Submitted for review") -> 0 | G18: =COUNTIFS('SDLC G0-G6'!$A$5:$A$109,B18,'SDLC G0-G6'!$G$5:$G$109,"Not applicable")+COUNTIFS('SDLC G0-G6'!$A$5:$A$109,B18,'SDLC G0-G6'!$G$5:$G$109,"Exception approved") -> 0 | H18: =D18-E18-G18 -> 11 | I18: =IFERROR(E18/(D18-G18),0) -> 0 | J18: =IF(D18-G18=0,"All items tailored out",IF(H18=0,"Evidence complete",H18&" item(s) outstanding")) -> 11 item(s) outstanding | K18: Not yet held
A19: SDLC | B19: G4 | C19: Release readiness authorisation | D19: =COUNTIF('SDLC G0-G6'!$A$5:$A$109,B19) -> 11 | E19: =COUNTIFS('SDLC G0-G6'!$A$5:$A$109,B19,'SDLC G0-G6'!$G$5:$G$109,"Complete") -> 0 | F19: =COUNTIFS('SDLC G0-G6'!$A$5:$A$109,B19,'SDLC G0-G6'!$G$5:$G$109,"In progress")+COUNTIFS('SDLC G0-G6'!$A$5:$A$109,B19,'SDLC G0-G6'!$G$5:$G$109,"Submitted for review") -> 0 | G19: =COUNTIFS('SDLC G0-G6'!$A$5:$A$109,B19,'SDLC G0-G6'!$G$5:$G$109,"Not applicable")+COUNTIFS('SDLC G0-G6'!$A$5:$A$109,B19,'SDLC G0-G6'!$G$5:$G$109,"Exception approved") -> 0 | H19: =D19-E19-G19 -> 11 | I19: =IFERROR(E19/(D19-G19),0) -> 0 | J19: =IF(D19-G19=0,"All items tailored out",IF(H19=0,"Evidence complete",H19&" item(s) outstanding")) -> 11 item(s) outstanding | K19: Not yet held
A20: SDLC | B20: G5 | C20: Operational acceptance | D20: =COUNTIF('SDLC G0-G6'!$A$5:$A$109,B20) -> 13 | E20: =COUNTIFS('SDLC G0-G6'!$A$5:$A$109,B20,'SDLC G0-G6'!$G$5:$G$109,"Complete") -> 0 | F20: =COUNTIFS('SDLC G0-G6'!$A$5:$A$109,B20,'SDLC G0-G6'!$G$5:$G$109,"In progress")+COUNTIFS('SDLC G0-G6'!$A$5:$A$109,B20,'SDLC G0-G6'!$G$5:$G$109,"Submitted for review") -> 0 | G20: =COUNTIFS('SDLC G0-G6'!$A$5:$A$109,B20,'SDLC G0-G6'!$G$5:$G$109,"Not applicable")+COUNTIFS('SDLC G0-G6'!$A$5:$A$109,B20,'SDLC G0-G6'!$G$5:$G$109,"Exception approved") -> 0 | H20: =D20-E20-G20 -> 13 | I20: =IFERROR(E20/(D20-G20),0) -> 0 | J20: =IF(D20-G20=0,"All items tailored out",IF(H20=0,"Evidence complete",H20&" item(s) outstanding")) -> 13 item(s) outstanding | K20: Not yet held
A21: SDLC | B21: G6 | C21: Retirement / closure | D21: =COUNTIF('SDLC G0-G6'!$A$5:$A$109,B21) -> 10 | E21: =COUNTIFS('SDLC G0-G6'!$A$5:$A$109,B21,'SDLC G0-G6'!$G$5:$G$109,"Complete") -> 0 | F21: =COUNTIFS('SDLC G0-G6'!$A$5:$A$109,B21,'SDLC G0-G6'!$G$5:$G$109,"In progress")+COUNTIFS('SDLC G0-G6'!$A$5:$A$109,B21,'SDLC G0-G6'!$G$5:$G$109,"Submitted for review") -> 0 | G21: =COUNTIFS('SDLC G0-G6'!$A$5:$A$109,B21,'SDLC G0-G6'!$G$5:$G$109,"Not applicable")+COUNTIFS('SDLC G0-G6'!$A$5:$A$109,B21,'SDLC G0-G6'!$G$5:$G$109,"Exception approved") -> 0 | H21: =D21-E21-G21 -> 10 | I21: =IFERROR(E21/(D21-G21),0) -> 0 | J21: =IF(D21-G21=0,"All items tailored out",IF(H21=0,"Evidence complete",H21&" item(s) outstanding")) -> 10 item(s) outstanding | K21: Not yet held
A22: SDLC | B22: All | C22: Track total | D22: =SUM(D14:D21) -> 89 | E22: =SUM(E14:E21) -> 0 | F22: =SUM(F14:F21) -> 0 | G22: =SUM(G14:G21) -> 0 | H22: =SUM(H14:H21) -> 89 | I22: =IFERROR(E22/(D22-G22),0) -> 0 | J22: =IF(H22=0,"All required evidence recorded",H22&" item(s) outstanding across the track") -> 89 item(s) outstanding across the track
A24: Reminder: a gate may be approved with conditions only when the conditions have owners and deadlines. Unresolved critical conditions cannot be treated this way, and a critical non-conformance blocks the gate unless a lawful, safe and time-bound exception is authorised.

Sheet PM Gates 1-7
A1: Project Management Track
A2: Source: Project Management Framework v1.1. One row per mandatory evidence item. Set Status, Owner and Evidence reference.
A4: Gate | B4: Gate decision point | C4: Stage | D4: Item | E4: Required evidence | F4: Decision owner / approver | G4: Status | H4: Owner | I4: Due date | J4: Date completed | K4: Evidence reference | L4: Notes
A5: Gate 1 - Intake decision
A6: Exit criteria: The need is real enough to investigate, an idea owner is identified, the work supports institutional or client value, and feasibility effort is justified.
A7: Gate 1 | B7: Intake decision | C7: Stage 1 - Strategic Intake and Opportunity Definition | D7: Gate 1.01 | E7: Project idea / intake record: problem or opportunity, proposed outcome, beneficiaries, owner, urgency and known constraints | F7: Sponsor for Class C, ratified in batch at the monthly Project Authority review; Project Authority for Class A and Class B | G7: Not started
A8: Gate 1 | B8: Intake decision | C8: Stage 1 - Strategic Intake and Opportunity Definition | D8: Gate 1.02 | E8: Current situation described with evidence that a problem or opportunity exists | F8: Sponsor for Class C, ratified in batch at the monthly Project Authority review; Project Authority for Class A and Class B | G8: Not started
A9: Gate 1 | B9: Intake decision | C9: Stage 1 - Strategic Intake and Opportunity Definition | D9: Gate 1.03 | E9: Affected users, clients, services and institutional goals identified | F9: Sponsor for Class C, ratified in batch at the monthly Project Authority review; Project Authority for Class A and Class B | G9: Not started
A10: Gate 1 | B10: Intake decision | C10: Stage 1 - Strategic Intake and Opportunity Definition | D10: Gate 1.04 | E10: Expected outcome stated without assuming a solution too early | F10: Sponsor for Class C, ratified in batch at the monthly Project Authority review; Project Authority for Class A and Class B | G10: Not started
A11: Gate 1 | B11: Intake decision | C11: Stage 1 - Strategic Intake and Opportunity Definition | D11: Gate 1.05 | E11: Initial screening for legal, ethical, security, privacy, safety, financial and reputational concerns | F11: Sponsor for Class C, ratified in batch at the monthly Project Authority review; Project Authority for Class A and Class B | G11: Not started
A12: Gate 1 | B12: Intake decision | C12: Stage 1 - Strategic Intake and Opportunity Definition | D12: Gate 1.06 | E12: Urgency, rough scale and project-versus-operations judgement recorded | F12: Sponsor for Class C, ratified in batch at the monthly Project Authority review; Project Authority for Class A and Class B | G12: Not started
A13: Gate 1 | B13: Intake decision | C13: Stage 1 - Strategic Intake and Opportunity Definition | D13: Gate 1.07 | E13: Comparison against active commitments and resource capacity | F13: Sponsor for Class C, ratified in batch at the monthly Project Authority review; Project Authority for Class A and Class B | G13: Not started
A14: Gate 1 | B14: Intake decision | C14: Stage 1 - Strategic Intake and Opportunity Definition | D14: Gate 1.08 | E14: Initial classification proposed (Class A / B / C) with reasons | F14: Sponsor for Class C, ratified in batch at the monthly Project Authority review; Project Authority for Class A and Class B | G14: Not started
A15: Gate 1 | B15: Intake decision | C15: Stage 1 - Strategic Intake and Opportunity Definition | D15: Gate 1.09 | E15: Portfolio recommendation: proceed to feasibility, defer, merge, return or decline | F15: Sponsor for Class C, ratified in batch at the monthly Project Authority review; Project Authority for Class A and Class B | G15: Not started
A16: Gate 1 | B16: Intake decision | C16: Stage 1 - Strategic Intake and Opportunity Definition | D16: Gate 1.10 | E16: Gate 1 decision recorded with approver, date and conditions | F16: Sponsor for Class C, ratified in batch at the monthly Project Authority review; Project Authority for Class A and Class B | G16: Not started
A17: Gate 1 | B17: Intake decision | C17: Stage 1 - Strategic Intake and Opportunity Definition | D17: Gate 1.11 | E17: Expedited Gate 1/2 path used? If yes, record urgency justification, authority, maximum spend, time limit and stop authority (Section 4.6) | F17: Sponsor for Class C, ratified in batch at the monthly Project Authority review; Project Authority for Class A and Class B | G17: Not started
A18: Gate 2 - Project authorisation
A19: Exit criteria: A sponsor accepts accountability; the business case is credible; scope and intended outcome are clear; major risks are understood; suitable resources are likely available; and feasibility evidence supports proceeding.
A20: Gate 2 | B20: Project authorisation | C20: Stage 2 - Initiation and Feasibility | D20: Gate 2.01 | E20: Project charter completed against the Appendix B template | F20: Sponsor for Class B/C; Project Authority for Class A | G20: Not started
A21: Gate 2 | B21: Project authorisation | C21: Stage 2 - Initiation and Feasibility | D21: Gate 2.02 | E21: Proportionate business case prepared | F21: Sponsor for Class B/C; Project Authority for Class A | G21: Not started
A22: Gate 2 | B22: Project authorisation | C22: Stage 2 - Initiation and Feasibility | D22: Gate 2.03 | E22: Feasibility assessed: strategic, technical, operational, economic, schedule, legal/contractual, ethical/social and resource dimensions | F22: Sponsor for Class B/C; Project Authority for Class A | G22: Not started
A23: Gate 2 | B23: Project authorisation | C23: Stage 2 - Initiation and Feasibility | D23: Gate 2.04 | E23: Alternative approaches identified, including do nothing, buy, build, partner or change the process | F23: Sponsor for Class B/C; Project Authority for Class A | G23: Not started
A24: Gate 2 | B24: Project authorisation | C24: Stage 2 - Initiation and Feasibility | D24: Gate 2.05 | E24: High-level scope, exclusions, assumptions and acceptance concept prepared | F24: Sponsor for Class B/C; Project Authority for Class A | G24: Not started
A25: Gate 2 | B25: Project authorisation | C25: Stage 2 - Initiation and Feasibility | D25: Gate 2.06 | E25: Cost, duration, resource demand and expected benefits estimated as ranges where uncertainty is high | F25: Sponsor for Class B/C; Project Authority for Class A | G25: Not started
A26: Gate 2 | B26: Project authorisation | C26: Stage 2 - Initiation and Feasibility | D26: Gate 2.07 | E26: Principal risks, dependencies and constraints identified | F26: Sponsor for Class B/C; Project Authority for Class A | G26: Not started
A27: Gate 2 | B27: Project authorisation | C27: Stage 2 - Initiation and Feasibility | D27: Gate 2.08 | E27: Sponsor, project manager and key decision makers nominated | F27: Sponsor for Class B/C; Project Authority for Class A | G27: Not started
A28: Gate 2 | B28: Project authorisation | C28: Stage 2 - Initiation and Feasibility | D28: Gate 2.09 | E28: Software framework alignment recorded in the charter (software class, aligned G0-G6 checkpoints, Appendix I mapping) | F28: Sponsor for Class B/C; Project Authority for Class A | G28: Not started
A29: Gate 2 | B29: Project authorisation | C29: Stage 2 - Initiation and Feasibility | D29: Gate 2.10 | E29: Governance and tolerances recorded: decision rights, reporting, escalation, role separation, financial band, change authority | F29: Sponsor for Class B/C; Project Authority for Class A | G29: Not started
A30: Gate 2 | B30: Project authorisation | C30: Stage 2 - Initiation and Feasibility | D30: Gate 2.11 | E30: Benefits ownership, measures, default Gate 7 date and protected review effort recorded | F30: Sponsor for Class B/C; Project Authority for Class A | G30: Not started
A31: Gate 2 | B31: Project authorisation | C31: Stage 2 - Initiation and Feasibility | D31: Gate 2.12 | E31: Gate 2 decision recorded with approver, date and conditions | F31: Sponsor for Class B/C; Project Authority for Class A | G31: Not started
A32: Gate 3 - Delivery readiness
A33: Exit criteria: The integrated plan is realistic; funds and people are committed; key requirements and acceptance criteria are testable; material risks have responses; controls and reporting are ready; and the sponsor formally authorises execution.
A34: Gate 3 | B34: Delivery readiness | C34: Stage 3 - Detailed Planning and Baseline Approval | D34: Gate 3.01 | E34: Scope statement, deliverables, exclusions, requirements and acceptance criteria | F34: Sponsor for Class B/C; Project Authority for Class A | G34: Not started
A35: Gate 3 | B35: Delivery readiness | C35: Stage 3 - Detailed Planning and Baseline Approval | D35: Gate 3.02 | E35: Work breakdown structure with manageable work packages | F35: Sponsor for Class B/C; Project Authority for Class A | G35: Not started
A36: Gate 3 | B36: Delivery readiness | C36: Stage 3 - Detailed Planning and Baseline Approval | D36: Gate 3.03 | E36: Schedule with dependencies, milestones, estimates, critical constraints and contingency | F36: Sponsor for Class B/C; Project Authority for Class A | G36: Not started
A37: Gate 3 | B37: Delivery readiness | C37: Stage 3 - Detailed Planning and Baseline Approval | D37: Gate 3.04 | E37: Budget, procurement, staff effort, tools, infrastructure and reserves | F37: Sponsor for Class B/C; Project Authority for Class A | G37: Not started
A38: Gate 3 | B38: Delivery readiness | C38: Stage 3 - Detailed Planning and Baseline Approval | D38: Gate 3.05 | E38: Responsibility assignment and decision authority (Appendix H, one accountable per activity) | F38: Sponsor for Class B/C; Project Authority for Class A | G38: Not started
A39: Gate 3 | B39: Delivery readiness | C39: Stage 3 - Detailed Planning and Baseline Approval | D39: Gate 3.06 | E39: Quality plan, review points, test strategy and evidence required for acceptance | F39: Sponsor for Class B/C; Project Authority for Class A | G39: Not started
A40: Gate 3 | B40: Delivery readiness | C40: Stage 3 - Detailed Planning and Baseline Approval | D40: Gate 3.07 | E40: Risk register, response actions, issue process and escalation thresholds | F40: Sponsor for Class B/C; Project Authority for Class A | G40: Not started
A41: Gate 3 | B41: Delivery readiness | C41: Stage 3 - Detailed Planning and Baseline Approval | D41: Gate 3.08 | E41: Communication, stakeholder engagement and reporting calendar | F41: Sponsor for Class B/C; Project Authority for Class A | G41: Not started
...

Sheet SDLC G0-G6
A1: Software Development and Engineering Track
A2: Source: Software Development and Engineering Framework v1.2. One row per mandatory evidence item. Set Status, Owner and Evidence reference.
A4: Gate | B4: Gate decision point | C4: Stage | D4: Item | E4: Required evidence | F4: Decision owner / approver | G4: Status | H4: Owner | I4: Due date | J4: Date completed | K4: Evidence reference | L4: Notes
A5: G0 - Intake
A6: Exit criteria: The problem and intended benefits are clear enough to investigate; ownership and discovery resources are assigned; material legal, privacy, security or procurement blockers are identified; and management has approved, deferred or declined in writing.
A7: G0 | B7: Intake | C7: Stage 1 - Initiation and feasibility | D7: G0.01 | E7: Project request or concept note | F7: Sponsor and delivery lead | G7: Not started
A8: G0 | B8: Intake | C8: Stage 1 - Initiation and feasibility | D8: G0.02 | E8: Preliminary business case and feasibility assessment (technical, economic, operational, schedule, legal, data, security, resource) | F8: Sponsor and delivery lead | G8: Not started
A9: G0 | B9: Intake | C9: Stage 1 - Initiation and feasibility | D9: G0.03 | E9: Named sponsor, delivery lead and technical owner | F9: Sponsor and delivery lead | G9: Not started
A10: G0 | B10: Intake | C10: Stage 1 - Initiation and feasibility | D10: G0.04 | E10: Initial scope, stakeholder list, risk class and risk register | F10: Sponsor and delivery lead | G10: Not started
A11: G0 | B11: Intake | C11: Stage 1 - Initiation and feasibility | D11: G0.05 | E11: Alternatives considered, including process change, configuration or acquisition instead of custom development | F11: Sponsor and delivery lead | G11: Not started
A12: G0 | B12: Intake | C12: Stage 1 - Initiation and feasibility | D12: G0.06 | E12: Discovery effort estimated and authority to proceed obtained | F12: Sponsor and delivery lead | G12: Not started
A13: G0 | B13: Intake | C13: Stage 1 - Initiation and feasibility | D13: G0.07 | E13: G0 decision record | F13: Sponsor and delivery lead | G13: Not started
A14: G0 | B14: Intake | C14: Stage 1 - Initiation and feasibility | D14: G0.08 | E14: No coding started as an informal commitment before owner, outcome, data constraints and acceptance authority exist | F14: Sponsor and delivery lead | G14: Not started
A15: G1 - Requirements baseline
A16: Exit criteria: Each committed requirement is necessary, clear, feasible, testable, traceable and prioritised; conflicts and ambiguities are resolved or assigned with dates and owners; the acceptance authority approves the baseline; and scope, schedule and cost assumptions align with the approved requirements.
A17: G1 | B17: Requirements baseline | C17: Stage 2 - Discovery and requirements engineering | D17: G1.01 | E17: Software Requirements Specification, product backlog or equivalent controlled requirements set | F17: Product owner and delivery lead | G17: Not started
A18: G1 | B18: Requirements baseline | C18: Stage 2 - Discovery and requirements engineering | D18: G1.02 | E18: Functional requirements, business rules, data needs, interfaces, roles and permissions documented | F18: Product owner and delivery lead | G18: Not started
A19: G1 | B19: Requirements baseline | C19: Stage 2 - Discovery and requirements engineering | D19: G1.03 | E19: Non-functional requirements defined: security, privacy, performance, availability, reliability, accessibility, usability, compatibility, maintainability, scalability, portability, logging, backup and recovery | F19: Product owner and delivery lead | G19: Not started
A20: G1 | B20: Requirements baseline | C20: Stage 2 - Discovery and requirements engineering | D20: G1.04 | E20: User journeys, process maps, use cases or stories as appropriate | F20: Product owner and delivery lead | G20: Not started
A21: G1 | B21: Requirements baseline | C21: Stage 2 - Discovery and requirements engineering | D21: G1.05 | E21: Acceptance criteria and initial test conditions | F21: Product owner and delivery lead | G21: Not started
A22: G1 | B22: Requirements baseline | C22: Stage 2 - Discovery and requirements engineering | D22: G1.06 | E22: Data inventory and classification (Public / Internal / Confidential / Restricted) | F22: Product owner and delivery lead | G22: Not started
A23: G1 | B23: Requirements baseline | C23: Stage 2 - Discovery and requirements engineering | D23: G1.07 | E23: Preliminary privacy and security requirements | F23: Product owner and delivery lead | G23: Not started
A24: G1 | B24: Requirements baseline | C24: Stage 2 - Discovery and requirements engineering | D24: G1.08 | E24: Requirements traceability matrix or linked work-item structure | F24: Product owner and delivery lead | G24: Not started
A25: G1 | B25: Requirements baseline | C25: Stage 2 - Discovery and requirements engineering | D25: G1.09 | E25: Requirements reviewed with affected stakeholders and formally baselined | F25: Product owner and delivery lead | G25: Not started
A26: G1 | B26: Requirements baseline | C26: Stage 2 - Discovery and requirements engineering | D26: G1.10 | E26: Requirement quality rules applied: clear, atomic, feasible, testable, traceable, consistent, controlled | F26: Product owner and delivery lead | G26: Not started
A27: G1 | B27: Requirements baseline | C27: Stage 2 - Discovery and requirements engineering | D27: G1.11 | E27: Unresolved-question log with owners and dates | F27: Product owner and delivery lead | G27: Not started
A28: G1 | B28: Requirements baseline | C28: Stage 2 - Discovery and requirements engineering | D28: G1.12 | E28: G1 approval recorded | F28: Product owner and delivery lead | G28: Not started
A29: G2 - Design readiness
A30: Exit criteria: The design addresses the approved functional and non-functional requirements; interfaces, data ownership, trust boundaries and failure modes are understood; critical risks are reduced, accepted or assigned to a dated action; and build, test, deployment and operational approaches are feasible and funded.
A31: G2 | B31: Design readiness | C31: Stage 3 - Planning, architecture and detailed design | D31: G2.01 | E31: Project delivery plan and updated estimates | F31: Technical lead; security reviewer for higher risk | G31: Not started
A32: G2 | B32: Design readiness | C32: Stage 3 - Planning, architecture and detailed design | D32: G2.02 | E32: Assurance effort, schedule and budget as a distinct line item; commercial disclosure for Class 3 and Class 4 client work | F32: Technical lead; security reviewer for higher risk | G32: Not started
A33: G2 | B33: Design readiness | C33: Stage 3 - Planning, architecture and detailed design | D33: G2.03 | E33: Architecture description with context, component, deployment and data-flow views | F33: Technical lead; security reviewer for higher risk | G33: Not started
A34: G2 | B34: Design readiness | C34: Stage 3 - Planning, architecture and detailed design | D34: G2.04 | E34: Architecture Decision Records for material choices, including rejected alternatives | F34: Technical lead; security reviewer for higher risk | G34: Not started
A35: G2 | B35: Design readiness | C35: Stage 3 - Planning, architecture and detailed design | D35: G2.05 | E35: UX prototypes/designs, database model and API/interface specifications | F35: Technical lead; security reviewer for higher risk | G35: Not started
A36: G2 | B36: Design readiness | C36: Stage 3 - Planning, architecture and detailed design | D36: G2.06 | E36: Threat model and privacy assessment | F36: Technical lead; security reviewer for higher risk | G36: Not started
A37: G2 | B37: Design readiness | C37: Stage 3 - Planning, architecture and detailed design | D37: G2.07 | E37: Security design: authentication, authorisation, secrets, encryption, logging and recovery controls | F37: Technical lead; security reviewer for higher risk | G37: Not started
A38: G2 | B38: Design readiness | C38: Stage 3 - Planning, architecture and detailed design | D38: G2.08 | E38: Test strategy, environment plan, migration approach, observability, support model, backup and rollback concept | F38: Technical lead; security reviewer for higher risk | G38: Not started
A39: G2 | B39: Design readiness | C39: Stage 3 - Planning, architecture and detailed design | D39: G2.09 | E39: Risky assumptions validated with controlled prototypes or spikes | F39: Technical lead; security reviewer for higher risk | G39: Not started
A40: G2 | B40: Design readiness | C40: Stage 3 - Planning, architecture and detailed design | D40: G2.10 | E40: Architecture expectations addressed: modularity, least privilege, failure containment, observability, recoverability, technology fitness | F40: Technical lead; security reviewer for higher risk | G40: Not started
A41: G2 | B41: Design readiness | C41: Stage 3 - Planning, architecture and detailed design | D41: G2.11 | E41: G2 review and approval record | F41: Technical lead; security reviewer for higher risk | G41: Not started
...

Sheet Artefact Floor
A1: Appendix A - mandatory artefact floor by software class
A2: R = required, C = conditional as stated, N/A = not applicable. Records may be combined; a required record may not be omitted without an approved exception.
A4: Stage | B4: Class 1 | C4: Class 2 | D4: Class 3 | E4: Class 4 | F4: Tailoring floor | G4: Owner | H4: Approval / evidence
A5: Initiation | B5: R-light | C5: R | D5: R | E5: R | F5: C1: purpose, owner, scope, risk class and disposal date. C2-4: request/charter, feasibility, stakeholders, scope and risk. | G5: Sponsor / delivery lead | H5: G0 decision
A6: Requirements | B6: C | C6: R | D6: R | E6: R | F6: C1: acceptance note; full requirements when user-facing, integrated or persistent data is used. C2-4: requirements/backlog, acceptance, data classification and traceability. | G6: Product owner / analyst | H6: G1 baseline
A7: Design | B7: C | C7: R-proportionate | D7: R | E7: R + independent review | F7: C1: design note for material interface, data or security risk. C2: architecture and test/deployment design. C3-4: add threat/privacy and specialist assurance. | G7: Technical lead | H7: G2 review
A8: Implementation | B8: R-light | C8: R | D8: R | E8: R | F8: Controlled source/configuration, review evidence, build/CI results and component inventory. C1 may use simplified review evidence but must retain source control and basic testing. | G8: Technical lead | H8: G3 code-complete record
A9: Testing | B9: R-basic | C9: R | D9: R + independent QA | E9: R + independent/specialist QA | F9: C1: basic acceptance and defect record. C2-4: plan, cases, results, defects, security/privacy and user acceptance at class depth. | G9: QA lead / product owner | H9: G4 recommendation
A10: Release | B10: C - non-production only | C10: R | D10: R | E10: R | F10: C1: demonstration/non-production release record only; any production use requires reclassification. C2-4: release notes, approval, migration, deployment, rollback and validation. | G10: Release / service owner | H10: G4 authorisation and deployment record
A11: Operations | B11: N/A - production prohibited | C11: R | D11: R | E11: R | F11: C2-4: runbooks, monitoring, access, backup/recovery, support, incidents, targets and reviews. A Class 1 experiment must be reclassified before operational reliance. | G11: Service owner | H11: G5 acceptance and service reviews
A12: Closure | B12: R | C12: R | D12: R | E12: R | F12: C1: disposal date, access removal and data/code disposition. C2-4: acceptance/closure, data disposition, decommissioning, archive and lessons. | G12: Sponsor / service owner | H12: G6 decision

Sheet Framework Alignment
A1: Appendix I - project and software framework reconciliation
A2: Evidence is created once and referenced by both tracks. The higher classification, stronger control and more senior approver govern wherever the mappings differ.
A4: Project gate | B4: Software checkpoint | C4: Consolidation rule
A5: Gate 1 - Intake | B5: G0 - Intake | C5: Use one intake record, sponsor, feasibility screen and initial classification decision.
A6: Gate 2 - Project Authorisation | B6: G1 - Requirements Baseline | C6: Combine when requirements and acceptance criteria are sufficiently mature. If G1 follows later, reuse the charter and add only the requirements evidence; do not repeat the business decision.
A7: Gate 3 - Delivery Readiness | B7: G2 - Design Readiness | C7: Use one integrated readiness pack covering project baseline, architecture, security/privacy, test, deployment, assurance and operational plans.
A8: Gate 4 - Release Readiness | B8: G3 prerequisite and G4 - Release Readiness | C8: G3 code-complete evidence is an engineering prerequisite. One G4/Gate 4 approval pack authorises release under the stricter approver set.
A9: Gate 5 - Continuation / Exception | B9: G3 or G5 evidence where relevant | C9: Gate 5 is recurring or triggered project governance. Engineering or early-life evidence may support it; no duplicate gate is required solely because numbering differs.
A10: Gate 6 - Closure | B10: G5 - Operational Acceptance and G6 - Retirement/Closure | C10: Use G5 evidence for handover. Use G6 when the project closes or a service is retired. One closure record may satisfy both where scope matches.
A11: Gate 7 - Benefits | B11: Post-implementation review evidence; no separate software gate | C11: Use service measures and the software review as evidence for the single Gate 7 benefits decision.
A13: Classification mapping
A14: Project class | B14: Normal software class | C14: Mandatory interpretation
A15: Class C - Small / Low Risk | B15: Software Class 1 or Class 2 | C15: Class 1 is permitted only for time-bound, non-production experimentation with no real personal, client-confidential or payment data. Any operational or production use is at least Class 2.
A16: Class B - Standard / Medium Risk | B16: Software Class 2 or Class 3 | C16: Use Class 3 where personal/sensitive data, public exposure, finance/identity, material reputation, contractual service levels or significant recovery impact exists.
A17: Class A - Strategic / High Risk | B17: Software Class 3 or Class 4 | C17: Use Class 4 for safety-significant, critical-infrastructure, large-scale restricted-data or mission-critical services. Executive governance and explicit residual-risk acceptance apply.

Sheet Risk and Issue Register
A1: Risk and Issue Register
A2: Use the form: Because of [cause], there is a possibility that [uncertain event], resulting in [effect on objectives]. For issues, state what has happened, current impact, immediate containment, root-cause owner and resolution date.
A4: ID | B4: Risk or issue statement | C4: Type | D4: Category | E4: Likelihood | F4: Impact | G4: Rating | H4: Owner | I4: Response | J4: Action | K4: Due | L4: Residual risk | M4: Status | N4: Last review | O4: Next review
A5: R-001 | B5: Because the bank API sandbox has no certification slot before November, there is a possibility that connectivity testing slips, resulting in a Gate 4 delay | C5: Risk | D5: Technical | E5: Medium | F5: High | G5: High | H5: Technical Lead | I5: Reduce | J5: Book a certification slot and prepare an aggregator fallback path | K5: 2026-10-15 | L5: Moderate | M5: Open | N5: 2026-09-15 | O5: 2026-09-29
A27: Row 5 is a worked example. Delete it or keep it below your live entries.

Sheet Change Requests
A1: Change Requests
A2: A change becomes part of the project only after need, impact, alternatives, risks, cost, schedule, quality and benefits are assessed and the correct authority approves it.
A4: Change ID | B4: Date | C4: Requester | D4: Requested change and reason | E4: Urgency and consequence of delay | F4: Scope and requirements impact | G4: Schedule and milestone impact | H4: Cost, resources and procurement impact | I4: Quality, security, privacy and operational impact | J4: Risk, benefit and stakeholder impact | K4: Options considered | L4: Recommendation | M4: Decision and conditions | N4: Change authority | O4: Baselines updated by | P4: Implementation verified
A5: CR-001 | B5: 2026-09-20 | C5: Product Owner | D5: Add multi-currency display conversion to the first release | E5: Medium - client demonstration on 12 November | F5: Adds 3 requirements and 2 acceptance criteria | G5: +5 business days on the build milestone | H5: +GHS 4,000 contractor effort | I5: Adds an exchange-rate dependency requiring availability monitoring | J5: Improves client acceptance likelihood; adds a third-party dependency risk | K5: Reject / defer / substitute / reduce other scope / approve | L5: Approve with a rate-provider fallback | M5: Approved with conditions | N5: Project Sponsor | O5: Project Manager | P5: Pending
A27: Row 5 is a worked example. Delete it or keep it below your live entries.

Sheet Exceptions
A1: Exceptions
A2: Types: Exception (approved, time-bound deviation) or Non-conformance (required process or evidence absent, inaccurate or bypassed). An expired exception is non-compliance. An exception may never authorise unlawful conduct. Critical non-conformance blocks the relevant gate.
A4: Exception ID | B4: Date raised | C4: Type | D4: Exact requirement that cannot be met | E4: Business and technical reason | F4: Affected systems, data, users | G4: Duration | H4: Risk assessment | I4: Accountable risk owner | J4: Compensating controls | K4: Validation evidence | L4: Remediation plan and owner | M4: Expiry date | N4: Approval level and approver | O4: Status
A5: EX-001 | B5: 2026-09-22 | C5: Exception | D5: Independent QA for a Class 3 release (Appendix A testing floor) | E5: No second qualified tester available in the delivery window | F5: Bank connectivity module; no personal data in test | G5: Until 2026-11-30 | H5: Moderate residual risk of undetected regression | I5: Technical Lead | J5: External reviewer appointed for regression evidence; extended smoke test set | K5: Reviewer report and test results attached | L5: Recruit or contract a QA reviewer before the next release - Delivery Lead | M5: 2026-11-30 | N5: Project Authority | O5: Open
A27: Row 5 is a worked example. Delete it or keep it below your live entries.

Sheet Emergency Changes
A1: Emergency Changes
A2: Software, production-service or client-data emergencies follow the SDLC emergency-change procedure: named authority and deputy, non-waivable minimum record, deferrable-evidence list and a retrospective review within 72 hours of stabilisation. All other projects: Sponsor records the same elements and convenes a review within 5 business days.
A4: Emergency ID | B4: Incident / change identifier | C4: Date and time | D4: Requester | E4: Authoriser | F4: Operator | G4: Reason (contain / restore / prevent harm / urgent security) | H4: Scope | I4: Least-privileged access used | J4: Activity logs protected | K4: Backup taken or reason unsafe | L4: Rollback or containment path | M4: Smoke / safety verification | N4: Deferred evidence and owners | O4: Due dates | P4: Retrospective review date | Q4: Review outcome | R4: Repeat? Problem record raised
A5: EM-001 | B5: INC-2026-041 | C5: 2026-11-04 22:10 | D5: On-call engineer | E5: Service Owner | F5: DevOps engineer | G5: Restore a failed service | H5: Payments read API pod restart and config rollback | I5: Yes | J5: Yes | K5: Yes - snapshot 22:05 | L5: Revert to build 1.4.2 | M5: Smoke suite passed 22:35 | N5: Full regression pack; final release notes | O5: 2026-11-07 | P5: 2026-11-06 | Q5: Change retained; root cause assigned | R5: No
A27: Row 5 is a worked example. Delete it or keep it below your live entries.

Sheet Decision Log
A1: Decision Log
A2: Gate decisions are one of: Approve, Approve with conditions, Hold, Redirect, Terminate. Unresolved critical conditions cannot be treated as 'approve with conditions'.
A4: Decision ID | B4: Date | C4: Gate or trigger | D4: Decision requested | E4: Authority | F4: Evidence reviewed | G4: Decision | H4: Conditions | I4: Dissent recorded | J4: Condition owner | K4: Condition due date | L4: Status
A5: D-001 | B5: 2026-09-30 | C5: Gate 3 / G2 | D5: Approve baselines and authorise execution | E5: Project Sponsor | F5: Integrated plan, architecture, threat model, test strategy, benefits funding | G5: Approve with conditions | H5: Confirm the QA reviewer before the first build increment | I5: None | J5: Delivery Lead | K5: 2026-10-10 | L5: Open
A27: Row 5 is a worked example. Delete it or keep it below your live entries.

Sheet Measures
A1: Year-One mandatory measurement set
A2: Both frameworks make five measures mandatory from the effective date of 31 October 2026. Record the current value at the stated frequency.
A4: Track | B4: Measure and calculation | C4: Source / owner | D4: Frequency | E4: Year-One target | F4: Current value | G4: As at date
A5: PM | B5: Milestone reliability = milestones achieved on or before the approved date / milestones due | C5: Approved schedule and status reports / Project Manager; consolidated by Framework Owner | D5: Monthly | E5: At least 85% portfolio-wide
A6: PM | B6: Absolute cost forecast variance = |forecast total cost - approved budget| / approved budget | C6: Budget, commitments and forecast / Project Manager and Finance | D6: Monthly | E6: Within class tolerance: A 5%, B 10%, C 15%
A7: PM | B7: First-pass acceptance rate = deliverables accepted without material rework / deliverables presented | C7: Acceptance and defect records / Quality Reviewer or acceptance authority | D7: At each acceptance event; quarterly portfolio total | E7: At least 90%
A8: PM | B8: Overdue critical risk actions = count of critical-risk actions past their approved due date | C8: Risk register / Project Manager; challenged by Assurance | D8: Weekly on project; monthly portfolio total | E8: Zero overdue critical actions
A9: PM | B9: On-time Gate 7 completion = Gate 7 decisions completed by due date / Gate 7 reviews due | C9: Project register and benefits records / Framework Owner and Sponsor | D9: Monthly tracking; quarterly report | E9: 100% completed on time
A10: SDLC | B10: Delivery flow: median lead time from authorised work item to accepted release, with material delay reasons | C10: Delivery lead | D10: Monthly | E10: Set by project; trend must not deteriorate
A11: SDLC | B11: Defect escape rate = production defects / total defects found in testing and production, reported with severity | C11: QA lead | D11: Per release and quarterly | E11: Set by project; severity trend reported
A12: SDLC | B12: Availability: observed production-service availability against the approved service target | C12: Service owner | D12: Monthly | E12: Approved service target
A13: SDLC | B13: Open vulnerability age by severity against institutional service targets | C13: Technical / security owner | D13: Monthly | E13: Within the Class service targets
A14: SDLC | B14: Gate compliance = applicable gates with required evidence and approval recorded before the governed commitment | C14: Freston Kenny Adedeme, Framework Owner | D14: Quarterly | E14: 100%
